Workbook

Sheet Dashboard
J10: Company Registered Name : Marico Limited | U10: Sector: FMCG | Y10: TICKER: MARICO | AD10: BSE CODE: 531642 | AI10: CMP: 791

Sheet About
B10: Peer companies
E12: Name of Company | L12: Country | O12: CMP | R12: Market Capital | U12: Revenue Growth (%) | AA12: Profit Growth (%)
E14: Patanjali Foods | L14: India | O14: 511.4 | R14: 55636.15 | W14: 19.12 | AB14: 46.16
E15: Sundrop Brands | L15: India | O15: 644.75 | R15: 2430.52 | W15: 89.65 | AB15: 470.6
E16: Gokul Agro | L16: India | O16: 170.15 | R16: 5020.92 | W16: 29.47 | AB16: 24.09
E17: CIAN Agro | L17: India | O17: 1307.2 | R17: 3658.3 | W17: 230.97 | AB17: 355.15
E18: Shri Venkatesh | L18: India | O18: 250.95 | R18: 555.08 | W18: 59.19 | AB18: 70.28
B21: Shareholding pattern
E23: Investors | M23: 2025 | S23: Major Shareholders
E24: Shareholders | J24: March | L24: June | N24: Septemer | P24: December
E26: Promoters | J26: 0.5905 | L26: 0.5903 | N26: 0.5894 | P26: 0.5893 | R26: Promoters | S26: Harsh C Mariwala with Late Kishore V Mariwala for Gemini Family Trust
E27: FIIs | J27: 0.2362 | L27: 0.2362 | N27: 0.2412 | P27: 0.2402 | R27: FIIs | S27: First Sentier Investors Icvc- Stewart Investors Asia Pacific Leaders Fund
E28: DIIs | J28: 0.1412 | L28: 0.1412 | N28: 0.1188 | P28: 0.1223 | R28: DIIs | S28: Life Insurance Corporation of India
E29: Government | J29: 0.001 | L29: 0.001 | N29: 0.0011 | P29: 0.0011
E30: Public | J30: 0.0451 | L30: 0.0453 | N30: 0.0458 | P30: 0.0449
E31: Others | J31: 0.0012 | L31: 0.0012 | N31: 0.0026 | P31: 0.0022
B34: Recent Updates
E36: Q3 Performance and Growth : Marico reported a 13.3% rise in consolidated net profit to Rs. 460 Crore for the Decemeber quarter , driven by 8% domestic volume growth and
E37: strong internation expansion
E39: Acquisition Spree : In february 2026, Maricp announced the acquisition of a 75% stake in Vietnam's SKINETIQ for Rs. 262 crore and a 60% stake in Indian plant -based brand Cosmix
E40: , following a January deal for 4700BC popcorn
E42: Stock Record Highs: Shares hit fresh record highs in February 2026, with analysts setting targets as high as Rs. 900-950 on a strong premiumization and growth in new businesses
E44: Strategic Outlook : The company is focusing on expanding its digital-first , premium beauty , and wellness portfolio to achieve sustained growth
E46: Margin Outlook: Management expects margin expansion of 150-200 basic points in the near ro medium term , supported by easing input costs.

Sheet Income statement
E2: ARICO LTD
B10: PARTICULARS | C10: 2021 A | D10: 2022 A | E10: 2023A | F10: 2024A | G10: 2025A | H10: 2026 E | I10: 2027 E | J10: 2028 E | K10: 2029 E | L10: 2030 E
B12: Revenue growth (%) | D12: =D14/C14-1 -> 0.18190855 | E12: =E14/D14-1 -> 0.026492851 | F12: =F14/E14-1 -> -0.011368292 | G12: =G14/F14-1 -> 0.1220346 | H12: =H14/G14-1 -> 0.13423806 | I12: =I14/H14-1 -> 0.14766187 | J12: =J14/I14-1 -> 0.16242805 | K12: =K14/J14-1 -> 0.17867086 | L12: =L14/K14-1 -> 0.19653794
B13: Revenue :
B14: Revenue from operations | C14: 8048 | D14: 9512 | E14: 9764 | F14: 9653 | G14: 10831 | H14: ='Revenue schedule'!H15 -> 12284.932 | I14: ='Revenue schedule'!I15 -> 14098.948 | J14: ='Revenue schedule'!J15 -> 16389.013 | K14: ='Revenue schedule'!K15 -> 19317.252 | L14: ='Revenue schedule'!L15 -> 23113.825
B15: Other income | C15: 94 | D15: 98 | E15: 144 | F15: 142 | H15: =G15 -> 0 | I15: =H15 -> 0 | J15: =I15 -> 0 | K15: =J15 -> 0 | L15: =K15 -> 0
B16: Total Income | C16: =SUM(C14:C15) -> 8142 | D16: =SUM(D14:D15) -> 9610 | E16: =SUM(E14:E15) -> 9908 | F16: =SUM(F14:F15) -> 9795 | G16: =SUM(G14:G15) -> 10831 | H16: =SUM(H14:H15) -> 12284.932 | I16: =SUM(I14:I15) -> 14098.948 | J16: =SUM(J14:J15) -> 16389.013 | ... L16: =SUM(L14:L15) -> 23113.825
B17: Expenses :
B18: Cost of material consumed | C18: 3884 | D18: 5061 | E18: 4649 | F18: 3941 | G18: 4572 | H18: ='Cost Schedule'!H15 -> 5691.2646 | I18: ='Cost Schedule'!I15 -> 6525.0077 | J18: ='Cost Schedule'!J15 -> 7457.8735 | K18: ='Cost Schedule'!K15 -> 8690.3053 | L18: ='Cost Schedule'!L15 -> 10482.453
B19: Purchases of stock in trade | C19: 339 | D19: 491 | E19: 541 | F19: 752 | G19: 960 | H19: ='Cost Schedule'!H16 -> 787.76528 | I19: ='Cost Schedule'!I16 -> 903.16913 | J19: ='Cost Schedule'!J16 -> 1032.2932 | K19: ='Cost Schedule'!K16 -> 1202.8822 | L19: ='Cost Schedule'!L16 -> 1450.9451
B20: Changes in inventories of finished goods , stock in trade and work in progress | C20: 47 | D20: -116 | E20: 161 | F20: 55 | G20: -144 | H20: ='Cost Schedule'!H17 -> 5.9836009 | I20: ='Cost Schedule'!I17 -> 6.8601698 | J20: ='Cost Schedule'!J17 -> 7.840953 | K20: ='Cost Schedule'!K17 -> 9.1366897 | L20: ='Cost Schedule'!L17 -> 11.020892
B21: COGS | C21: =SUM(C18:C20) -> 4270 | D21: =SUM(D18:D20) -> 5436 | E21: =SUM(E18:E20) -> 5351 | F21: =SUM(F18:F20) -> 4748 | G21: =SUM(G18:G20) -> 5388 | H21: =SUM(H18:H20) -> 6485.0135 | I21: =SUM(I18:I20) -> 7435.037 | J21: =SUM(J18:J20) -> 8498.0077 | ... L21: =SUM(L18:L20) -> 11944.419
B22: Employee benefit expense | C22: 570 | D22: 586 | E22: 653 | F22: 743 | G22: 831 | H22: ='Cost Schedule'!H29 -> 867.32821 | I22: ='Cost Schedule'!I29 -> 995.39952 | J22: ='Cost Schedule'!J29 -> 1157.0803 | K22: ='Cost Schedule'!K29 -> 1363.8169 | L22: ='Cost Schedule'!L29 -> 1631.8586
B23: Finance Costs | C23: 34 | D23: 39 | E23: 56 | F23: 73 | G23: 53 | H23: ='Debt Schedule'!H37 -> 58.849927 | I23: ='Debt Schedule'!I37 -> 61.606184 | J23: ='Debt Schedule'!J37 -> 65.133903 | K23: ='Debt Schedule'!K37 -> 69.641292 | L23: ='Debt Schedule'!L37 -> 75.413253
B24: Depreciation and amortisation | C24: 139 | D24: 139 | E24: 155 | F24: 158 | G24: 178 | H24: =-('Asset Schedule'!H34) -> 226.24873 | I24: =-('Asset Schedule'!I34) -> 226.9313 | J24: =-('Asset Schedule'!J34) -> 236.17127 | K24: =-('Asset Schedule'!K34) -> 256.22074 | L24: =-('Asset Schedule'!L34) -> 286.85566
B25: Other expenses | C25: 1617 | D25: 1809 | E25: 1950 | F25: 2136 | G25: 2473 | H25: ='Cost Schedule'!H34 -> 2556.293 | I25: ='Cost Schedule'!I34 -> 2933.76 | J25: ='Cost Schedule'!J34 -> 3410.2849 | K25: ='Cost Schedule'!K34 -> 4019.6034 | L25: ='Cost Schedule'!L34 -> 4809.608
B26: Total Expenses | C26: =SUM(C21:C25) -> 6630 | D26: =SUM(D21:D25) -> 8009 | E26: =SUM(E21:E25) -> 8165 | F26: =SUM(F21:F25) -> 7858 | G26: =SUM(G21:G25) -> 8923 | H26: =SUM(H21:H25) -> 10193.733 | I26: =SUM(I21:I25) -> 11652.734 | J26: =SUM(J21:J25) -> 13366.678 | ... L26: =SUM(L21:L25) -> 18748.154
B27: Profit before share of net profits of investments and exceptional items | C27: =C16-C26 -> 1512 | D27: =D16-D26 -> 1601 | E27: =E16-E26 -> 1743 | F27: =F16-F26 -> 1937 | G27: =G16-G26 -> 1908 | H27: =H16-H26 -> 2091.1991 | I27: =I16-I26 -> 2446.2146 | J27: =J16-J26 -> 3022.3352 | ... L27: =L16-L26 -> 4365.6713
B28: Share of net gain/(loss) of joint ventures | C28: -2 | D28: 0 | E28: 0 | F28: 0 | G28: 0 | H28: 0 | I28: 0 | J28: 0 | K28: 0 | L28: 0
B29: Profit before exceptional items | C29: =SUM(C27:C28) -> 1510 | D29: =SUM(D27:D28) -> 1601 | E29: =SUM(E27:E28) -> 1743 | F29: =SUM(F27:F28) -> 1937 | G29: =SUM(G27:G28) -> 1908 | H29: =SUM(H27:H28) -> 2091.1991 | I29: =SUM(I27:I28) -> 2446.2146 | J29: =SUM(J27:J28) -> 3022.3352 | ... L29: =SUM(L27:L28) -> 4365.6713
B30: Exceptional Items | C30: 13 | D30: 0 | E30: 0 | F30: 0 | G30: 0 | H30: 0 | I30: 0 | J30: 0 | K30: 0 | L30: 0
B31: Profit before Tax | C31: =SUM(C29:C30) -> 1523 | D31: =D29-D30 -> 1601 | E31: =E29-E30 -> 1743 | F31: =F29-F30 -> 1937 | G31: =G29-G30 -> 1908 | H31: =H29-H30 -> 2091.1991 | I31: =I29-I30 -> 2446.2146 | J31: =J29-J30 -> 3022.3352 | K31: =K29-K30 -> 3705.6458 | L31: =L29-L30 -> 4365.6713
B32: Income Tax Expense
B33: (a) Current Tax | C33: 335 | D33: 343 | E33: 377 | F33: 353 | G33: 480 | H33: ='Cost Schedule'!H44 -> 587.73931 | I33: ='Cost Schedule'!I44 -> 698.62473 | J33: ='Cost Schedule'!J44 -> 876.4666 | K33: ='Cost Schedule'!K44 -> 1063.9023 | L33: ='Cost Schedule'!L44 -> 1262.3167
B34: (b) Deffered Tax | C34: -11 | D34: 3 | E34: 44 | F34: 82 | G34: -22 | H34: ='Cost Schedule'!H45 -> 27.012667 | I34: ='Cost Schedule'!I45 -> 32.108992 | J34: ='Cost Schedule'!J45 -> 40.282655 | K34: ='Cost Schedule'!K45 -> 48.897251 | L34: ='Cost Schedule'!L45 -> 58.016435
B35: Total Tax | C35: =SUM(C33:C34) -> 324 | D35: =SUM(D33:D34) -> 346 | E35: =SUM(E33:E34) -> 421 | F35: =SUM(F33:F34) -> 435 | G35: =SUM(G33:G34) -> 458 | H35: =SUM(H33:H34) -> 614.75198 | I35: =SUM(I33:I34) -> 730.73373 | J35: =SUM(J33:J34) -> 916.74925 | ... L35: =SUM(L33:L34) -> 1320.3331
B36: Profit for the year (A) | C36: =C31-C35 -> 1199 | D36: =D31-D35 -> 1255 | E36: =E31-E35 -> 1322 | F36: =F31-F35 -> 1502 | G36: =G31-G35 -> 1450 | H36: =H31-H35 -> 1476.4471 | I36: =I31-I35 -> 1715.4808 | J36: =J31-J35 -> 2105.5859 | ... L36: =L31-L35 -> 3045.3381
B37: Other Comprehensive Income :
B38: Items that will not be reclassified to profit or loss
B39: Remeasurements of post employmet benefit obligations | C39: -1 | D39: 5 | E39: 2 | F39: 2 | G39: -1
B40: Income tax relating to items that will not be reclassified to profit or loss
B41: Remeasurements of post employmet benefit obligations | C41: 0 | D41: -1 | E41: 0 | F41: 0 | G41: 0
B42: Total | C42: =SUM(C38:C41) -> -1 | D42: =SUM(D38:D41) -> 4 | E42: =SUM(E38:E41) -> 2 | F42: =SUM(F38:F41) -> 2 | G42: 0 | H42: =SUM(H38:H41) -> 0 | I42: =SUM(I38:I41) -> 0 | J42: =SUM(J38:J41) -> 0 | K42: =SUM(K38:K41) -> 0 | L42: =SUM(L38:L41) -> 0
B43: Items that will be reclassified to profit or loss
B44: Exchange differences on translation of foreign obligations | C44: 5 | D44: 30 | E44: -34 | F44: -75 | G44: -75
B45: Change in fair value of hedging intruments | C45: 1 | D45: 1 | E45: 0 | F45: 0 | G45: 1
B46: Income tax relating to items that will be reclassified to profit or loss
B47: Change in fair value of hedging intruments | C47: 0 | D47: 0 | E47: 0 | F47: 0 | G47: 0
B48: Total | C48: =SUM(C43:C47) -> 6 | D48: =SUM(D43:D47) -> 31 | E48: =SUM(E43:E47) -> -34 | F48: =SUM(F43:F47) -> -75 | G48: =SUM(G43:G47) -> -74 | H48: =SUM(H43:H47) -> 0 | I48: =SUM(I43:I47) -> 0 | J48: =SUM(J43:J47) -> 0 | ... L48: =SUM(L43:L47) -> 0
B50: Other comprehensive income for the year (B) | C50: =SUM(C42,C48) -> 5 | D50: =SUM(D42,D48) -> 35 | E50: =SUM(E42,E48) -> -32 | F50: =SUM(F42,F48) -> -73 | G50: =SUM(G42,G48) -> -74 | H50: =SUM(H42,H48) -> 0 | I50: =SUM(I42,I48) -> 0 | J50: =SUM(J42,J48) -> 0 | ... L50: =SUM(L42,L48) -> 0
...

Sheet Balance Sheet
E2: ARICO LTD
B10: PARTICULARS | C10: 2021 A | D10: 2022 A | E10: 2023A | F10: 2024A | G10: 2025A | H10: 2026 E | I10: 2027 E | J10: 2028 E | K10: 2029 E | L10: 2030 E
B12: ASSETS
B14: Non-current Assets
B16: Property , plant and equipments | C16: 572 | D16: 600 | E16: 633 | F16: 700 | G16: 710 | H16: ='Asset Schedule'!H46 -> 852.077 | I16: ='Asset Schedule'!I46 -> 852.56334 | J16: ='Asset Schedule'!J46 -> 888.83882 | K16: ='Asset Schedule'!K46 -> 964.04807 | L16: ='Asset Schedule'!L46 -> 1080.6629
B17: Capital work in progress | C17: 24 | D17: 39 | E17: 67 | F17: 44 | G17: 40 | H17: ='Asset Schedule'!H47 -> 55.755392 | I17: ='Asset Schedule'!I47 -> 55.787215 | J17: ='Asset Schedule'!J47 -> 58.16089 | K17: ='Asset Schedule'!K47 -> 63.082184 | L17: ='Asset Schedule'!L47 -> 70.712842
B18: Right of use assets | C18: 180 | D18: 178 | E18: 175 | F18: 209 | G18: 230 | H18: ='Asset Schedule'!H48 -> 257.29842 | I18: ='Asset Schedule'!I48 -> 257.44528 | J18: ='Asset Schedule'!J48 -> 268.39925 | K18: ='Asset Schedule'!K48 -> 291.10989 | L18: ='Asset Schedule'!L48 -> 326.32364
B19: Investment properties | C19: 17 | D19: 22 | E19: 16 | F19: 15 | G19: 15 | H19: ='Asset Schedule'!H49 -> 23.62604 | I19: ='Asset Schedule'!I49 -> 23.639525 | J19: ='Asset Schedule'!J49 -> 24.645356 | K19: ='Asset Schedule'!K49 -> 26.730727 | L19: ='Asset Schedule'!L49 -> 29.964177
B20: Goodwill | C20: 613 | D20: 654 | E20: 862 | F20: 863 | G20: 857 | H20: =G20 -> 857 | I20: =H20 -> 857 | J20: =I20 -> 857 | K20: =J20 -> 857 | L20: =K20 -> 857
B21: Other intangible assets | C21: 230 | D21: 306 | E21: 560 | F21: 937 | G21: 946 | H21: ='Asset Schedule'!H50 -> 702.51756 | I21: ='Asset Schedule'!I50 -> 702.91854 | J21: ='Asset Schedule'!J50 -> 732.82682 | K21: ='Asset Schedule'!K50 -> 794.83509 | L21: ='Asset Schedule'!L50 -> 890.98133
B22: Investmet accounted for using the equity method | C22: 0 | D22: 0 | E22: 0 | F22: 0 | G22: 0 | H22: 0 | I22: 0 | J22: 0 | K22: 0 | L22: 0
B23: Financial assets
B24: (a) Investments | C24: 226 | D24: 187 | E24: 518 | F24: 343 | G24: 215 | H24: =G24 -> 215 | I24: =H24 -> 215 | J24: =I24 -> 215 | K24: =J24 -> 215 | L24: =K24 -> 215
B25: (b) Loans | C25: 4 | D25: 4 | E25: 4 | F25: 4 | G25: 6 | H25: =G25 -> 6 | I25: =H25 -> 6 | J25: =I25 -> 6 | K25: =J25 -> 6 | L25: =K25 -> 6
B26: (c) Other financial assets | C26: 41 | D26: 17 | E26: 32 | F26: 100 | G26: 22 | H26: =G26 -> 22 | I26: =H26 -> 22 | J26: =I26 -> 22 | K26: =J26 -> 22 | L26: =K26 -> 22
B27: Deffered tax assets (net) | C27: 186 | D27: 187 | E27: 146 | F27: 68 | G27: 57 | H27: =G27 -> 57 | I27: =H27 -> 57 | J27: =I27 -> 57 | K27: =J27 -> 57 | L27: =K27 -> 57
B28: Non current tax assets (net) | C28: 55 | D28: 57 | E28: 67 | F28: 95 | G28: 108 | H28: =G28 -> 108 | I28: =H28 -> 108 | J28: =I28 -> 108 | K28: =J28 -> 108 | L28: =K28 -> 108
B29: Other non current assets | C29: 26 | D29: 30 | E29: 46 | F29: 40 | G29: 49 | H29: =G29 -> 49 | I29: =H29 -> 49 | J29: =I29 -> 49 | K29: =J29 -> 49 | L29: =K29 -> 49
B30: Total non current assets | C30: =SUM(C16:C29) -> 2174 | D30: =SUM(D16:D29) -> 2281 | E30: =SUM(E16:E29) -> 3126 | F30: =SUM(F16:F29) -> 3418 | G30: =SUM(G16:G29) -> 3255 | H30: =SUM(H16:H29) -> 3205.2744 | I30: =SUM(I16:I29) -> 3206.3539 | J30: =SUM(J16:J29) -> 3286.8711 | ... L30: =SUM(L16:L29) -> 3712.6449
B32: Current Assets
B34: Inventories | C34: 1126 | D34: 1412 | E34: 1225 | F34: 1336 | G34: 1235 | H34: ='Working Capital Schedule'!H15 -> 1959.3166 | I34: ='Working Capital Schedule'!I15 -> 1754.016 | J34: ='Working Capital Schedule'!J15 -> 2504.5308 | K34: ='Working Capital Schedule'!K15 -> 2371.283 | L34: ='Working Capital Schedule'!L15 -> 3557.3125
B35: Financial Assets
B36: (a) Investments | C36: 628 | D36: 641 | E36: 578 | F36: 259 | G36: 1375 | H36: =G36 -> 1375 | I36: =H36 -> 1375 | J36: =I36 -> 1375 | K36: =J36 -> 1375 | L36: =K36 -> 1375
B37: (b) Trade receivables | C37: 388 | D37: 652 | E37: 1015 | F37: 1069 | G37: 1271 | H37: ='Working Capital Schedule'!H27 -> 754.2137 | I37: ='Working Capital Schedule'!I27 -> 1907.9981 | J37: ='Working Capital Schedule'!J27 -> 1270.8569 | K37: ='Working Capital Schedule'!K27 -> 2383.1785 | L37: ='Working Capital Schedule'!L27 -> 1857.0864
B38: (c) Cash and cash equivalents | C38: ='Cashflow statement'!C70 -> 109 | D38: ='Cashflow statement'!D70 -> 276 | E38: 207 | F38: 228 | G38: 321 | H38: ='Cashflow statement'!H70 -> 2148.78 | I38: ='Cashflow statement'!I70 -> 2994.86 | J38: ='Cashflow statement'!J70 -> 5300.2705 | K38: ='Cashflow statement'!K70 -> 7294.55 | L38: ='Cashflow statement'!L70 -> 6880.29
B39: (d) Bank balances other than above | C39: 835 | D39: 303 | E39: 549 | F39: 715 | G39: 456 | H39: =G39 -> 456 | I39: =H39 -> 456 | J39: =I39+277.87 -> 733.87 | K39: =J39 -> 733.87 | L39: =K39 -> 733.87
B40: (e) Loans receivables | C40: 6 | D40: 5 | E40: 4 | F40: 6 | G40: 7 | H40: =G40 -> 7 | I40: =H40 -> 7 | J40: =I40 -> 7 | K40: =J40 -> 7 | L40: =K40 -> 7
B41: (f) Other financial assets | C41: 5 | D41: 2 | E41: 4 | F41: 5 | G41: 3 | H41: =G41 -> 3 | I41: =H41 -> 3 | J41: =I41 -> 3 | K41: =J41 -> 3 | L41: =K41 -> 3
B42: Current Tax Assets ( Net) | C42: 1 | D42: 1 | E42: 2 | F42: 2 | G42: 2 | H42: =G42 -> 2 | I42: =H42 -> 2 | J42: =I42 -> 2 | K42: =J42 -> 2 | L42: =K42 -> 2
B43: Other current assets | C43: 224 | D43: 213 | E43: 229 | F43: 378 | G43: 413 | H43: =G43 -> 413 | I43: =H43 -> 413 | J43: =I43 -> 413 | K43: =J43 -> 413 | L43: =K43 -> 413
B44: Assets classified as held for sale | C44: 14 | D44: 0 | E44: 7 | F44: 5 | G44: 0 | H44: =G44 -> 0 | I44: =H44 -> 0 | J44: =I44 -> 0 | K44: =J44 -> 0 | L44: =K44 -> 0
B45: Total current assets | C45: =SUM(C34:C44) -> 3336 | D45: =SUM(D34:D44) -> 3505 | E45: =SUM(E34:E44) -> 3820 | F45: =SUM(F34:F44) -> 4003 | G45: =SUM(G34:G44) -> 5083 | H45: =SUM(H34:H44) -> 7118.3103 | I45: =SUM(I34:I44) -> 8912.8741 | J45: =SUM(J34:J44) -> 11609.528 | ... L45: =SUM(L34:L44) -> 14828.559
B47: TOTAL ASSETS | C47: =SUM(C30,C45) -> 5510 | D47: =SUM(D30,D45) -> 5786 | E47: =SUM(E30,E45) -> 6946 | F47: =SUM(F30,F45) -> 7421 | G47: =SUM(G30,G45) -> 8338 | H47: =(SUM(H30,H45)) -> 10323.585 | I47: =SUM(I30,I45) -> 12119.228 | J47: =SUM(J30,J45) -> 14896.399 | K47: =SUM(K30,K45) -> 18036.687 | L47: =SUM(L30,L45) -> 18541.204
B50: EQUITY AND LIABILITIES
B52: Equity
B54: Equity share capital | C54: 129 | D54: 129 | E54: 129 | F54: 129 | G54: 129 | H54: =G54 -> 129 | I54: =H54 -> 129 | J54: =I54 -> 129 | K54: =J54 -> 129 | L54: =K54 -> 129
B55: Other equity | C55: 3111 | D55: 3219 | E55: 3670 | F55: =3782-79 -> 3703 | G55: 3845 | H55: =G55+'Income statement'!I52+'Cashflow statement'!H63 -> 5107.4808 | I55: =H55+'Income statement'!J52+'Cashflow statement'!I63 -> 6760.0668 | J55: =I55+'Income statement'!K52+'Cashflow statement'!J63 -> 8899.9131 | K55: =J55+'Income statement'!L52+'Cashflow statement'!K63 -> 11492.251 | L55: =K55+'Income statement'!M52+'Cashflow statement'!L63 -> 11039.251
B56: Total share capital | C56: =SUM(C54:C55) -> 3240 | D56: =SUM(D54:D55) -> 3348 | E56: =SUM(E54:E55) -> 3799 | F56: =SUM(F54:F55) -> 3832 | G56: 3975 | H56: =SUM(H54:H55) -> 5236.4808 | I56: =SUM(I54:I55) -> 6889.0668 | J56: =SUM(J54:J55) -> 9028.9131 | K56: =SUM(K54:K55) -> 11621.251 | L56: =SUM(L54:L55) -> 11168.251
B57: Non-controlling interests | C57: 18 | D57: 57 | E57: 157 | F57: 337 | G57: 291 | H57: =G57 -> 291 | I57: =H57 -> 291 | J57: =I57 -> 291 | K57: =J57 -> 291 | L57: =K57 -> 291
B58: Total Equity | C58: =SUM(C56:C57) -> 3258 | D58: =SUM(D56:D57) -> 3405 | E58: =SUM(E56:E57) -> 3956 | F58: =SUM(F56:F57) -> 4169 | G58: =SUM(G56:G57) -> 4266 | H58: =SUM(H56:H57) -> 5527.4808 | I58: =SUM(I56:I57) -> 7180.0668 | J58: =SUM(J56:J57) -> 9319.9131 | ... L58: =SUM(L56:L57) -> 11459.251
...

Sheet Cashflow statement
E2: ARICO LTD
B10: PARTICULARS | C10: 2021 A | D10: 2022 A | E10: 2023A | F10: 2024A | G10: 2025A | H10: 2026 E | I10: 2027 E | J10: 2028 E | K10: 2029 E | L10: 2030 E
B13: CASH FLOW FROM OPERATING ACTIVITIES :
B15: Profit before tax | C15: ='Income statement'!C31 -> 1523 | D15: ='Income statement'!D27 -> 1601 | E15: ='Income statement'!E27 -> 1743 | F15: ='Income statement'!F27 -> 1937 | G15: ='Income statement'!G27 -> 1908 | H15: ='Income statement'!H27 -> 2091.1991 | I15: ='Income statement'!I27 -> 2446.2146 | J15: ='Income statement'!J27 -> 3022.3352 | K15: ='Income statement'!K27 -> 3705.6458 | L15: ='Income statement'!L27 -> 4365.6713
B16: Adjustments for :
B17: Depreciation and amortisation expense | C17: 139 | D17: 139 | E17: 155 | F17: 158 | G17: 178 | H17: ='Income statement'!H24 -> 226.24873 | I17: ='Income statement'!I24 -> 226.9313 | J17: ='Income statement'!J24 -> 236.17127 | K17: ='Income statement'!K24 -> 256.22074 | L17: ='Income statement'!L24 -> 286.85566
B18: Share of net loss/(gain) of joint ventures accounted for using the equity method | C18: 2 | D18: 0 | E18: 0 | F18: 0 | G18: 0
B19: Finance Costs | C19: 34 | D19: 39 | E19: 56 | F19: 73 | G19: 53 | H19: ='Income statement'!H23 -> 58.849927 | I19: ='Income statement'!I23 -> 61.606184 | J19: ='Income statement'!J23 -> 65.133903 | K19: ='Income statement'!K23 -> 69.641292 | L19: ='Income statement'!L23 -> 75.413253
B20: Interest income from financial asstes | C20: -59 | D20: -59 | E20: -49 | F20: -77 | G20: -77
B21: Profit on disposal of property, plant and equipments | C21: 0 | D21: 0 | E21: -28 | F21: -15 | G21: -20
B22: Net fair value changes in financial assets and profit on sale of investments | C22: -21 | D22: -29 | E22: -50 | F22: -73 | G22: -76
B23: Emplyoees stock option charge | C23: 9 | D23: 10 | E23: 19 | F23: 35 | G23: 43
B24: Impairement of Non-current assets and inventory | C24: 51 | D24: 0 | E24: 0 | F24: 0 | G24: 0
B25: Fair valuation gain on existing stake of Joint venture | C25: -64 | D25: 0 | E25: 0 | F25: 0 | G25: 0
B26: Provision for doubtful debts | C26: 3 | D26: 8 | E26: 1 | F26: 2 | G26: 2
B27: Operating profit before working capital changes | C27: =SUM(C15:C26) -> 1617 | D27: =SUM(D15:D26) -> 1709 | E27: =SUM(E15:E26) -> 1847 | F27: =SUM(F15:F26) -> 2040 | G27: =SUM(G15:G26) -> 2011 | H27: =SUM(H15:H26) -> 2376.2978 | I27: =SUM(I15:I26) -> 2734.752 | J27: =SUM(J15:J26) -> 3323.6404 | ... L27: =SUM(L15:L26) -> 4727.9402
B28: Changes in working capital :
B29: Decrease / (Increase) in inventories | C29: 251 | D29: -286 | E29: 191 | F29: -101 | G29: 101 | H29: ='Working Capital Schedule'!H14 -> 724.31659 | I29: ='Working Capital Schedule'!I14 -> -205.30063 | J29: ='Working Capital Schedule'!J14 -> 750.51486 | K29: ='Working Capital Schedule'!K14 -> -133.24782 | L29: ='Working Capital Schedule'!L14 -> 1186.0295
B30: (Increase) in trade receivables | C30: 147 | D30: -272 | E30: -360 | F30: -52 | G30: -205 | H30: ='Working Capital Schedule'!H26 -> -516.7863 | I30: ='Working Capital Schedule'!I26 -> 1153.7844 | J30: ='Working Capital Schedule'!J26 -> -637.14118 | K30: ='Working Capital Schedule'!K26 -> 1112.3216 | L30: ='Working Capital Schedule'!L26 -> -526.09203
B31: (Decrease) / Increase in trade payables | C31: 184 | D31: 210 | E31: 99 | F31: 106 | G31: -218 | H31: ='Working Capital Schedule'!H38 -> 537.11432 | I31: ='Working Capital Schedule'!I38 -> -59.083656 | J31: ='Working Capital Schedule'!J38 -> 593.94683 | K31: ='Working Capital Schedule'!K38 -> 112.67394 | L31: ='Working Capital Schedule'!L38 -> 914.86247
B32: Cash generated from (used in) operating activities | C32: =SUM(C27:C31) -> 2199 | D32: =SUM(D27:D31) -> 1361 | E32: =SUM(E27:E31) -> 1777 | F32: =SUM(F27:F31) -> 1993 | G32: =SUM(G27:G31) -> 1689 | H32: =SUM(H27:H31) -> 3120.9424 | I32: =SUM(I27:I31) -> 3624.1521 | J32: =SUM(J27:J31) -> 4030.9609 | ... L32: =SUM(L27:L31) -> 6302.7401
B33: Effect of exchange difference on translation of foreign currency | C33: 0 | D33: 0 | E33: 0 | F33: -49 | G33: -79
B34: Inxome taxes paid ( net of refunds ) | C34: -285 | D34: -351 | E34: -369 | F34: -378 | G34: -484 | H34: =-('Cost Schedule'!H46) -> -614.75198 | I34: =-('Cost Schedule'!I46) -> -730.73373 | J34: =-('Cost Schedule'!J46) -> -916.74925 | K34: =-('Cost Schedule'!K46) -> -1112.7995 | L34: =-('Cost Schedule'!L46) -> -1320.3331
B36: Net cash generated (used in) operating activities | C36: =SUM(C32:C34) -> 1914 | D36: =SUM(D32:D34) -> 1010 | E36: =SUM(E32:E34) -> 1408 | F36: =SUM(F32:F34) -> 1566 | G36: =SUM(G32:G34) -> 1126 | H36: =SUM(H32:H34) -> 2506.1904 | I36: =SUM(I32:I34) -> 2893.4184 | J36: =SUM(J32:J34) -> 3114.2116 | ... L36: =SUM(L32:L34) -> 4982.407
B38: CASH FLOW FROM INVESTING ACTIVITIES :
B40: Payment for property,plant and equipment and intangible assets | C40: -142 | D40: -132 | E40: -182 | F40: -153 | G40: -161 | H40: =-('Asset Schedule'!H23) -> -204.49503 | I40: =-('Asset Schedule'!I23) -> -260.69334 | J40: =-('Asset Schedule'!J23) -> -347.23557 | K40: =-('Asset Schedule'!K23) -> -456.84558 | L40: =-('Asset Schedule'!L23) -> -580.41876
B41: Acquisition of subsidiary under business combinatio net of cash | C41: -132 | D41: -55 | E41: -277 | F41: -103 | G41: 0
B42: Proceeds from sale of property, plant and equipment | C42: 5 | D42: 3 | E42: 25 | F42: 18 | G42: 39 | H42: =-('Asset Schedule'!H29) -> 27.971892 | I42: =-('Asset Schedule'!I29) -> 32.682552 | J42: =-('Asset Schedule'!J29) -> 30.547065 | K42: =-('Asset Schedule'!K29) -> 33.69002 | L42: =-('Asset Schedule'!L29) -> 34.724121
B43: Purchase of non current investments | C43: 164 | D43: -146 | E43: 0 | F43: 0 | G43: -46
B44: Proceeds from sale of non current investments | C44: 1 | D44: 0 | E44: 0 | F44: 233 | G44: 60
B45: (Payment for) / Proceeds from purchase / sale of investments | C45: -295 | D45: 215 | E45: -130 | F45: 147 | G45: -926
B46: (Purchase) / redemption of inter-corporate deposits | C46: 0 | D46: 3 | E46: -90 | F46: 200 | G46: 0
B47: (Investments in) / Redemption of bank deposits | C47: -591 | D47: 483 | E47: -259 | F47: -232 | G47: 343
B48: Interest received | C48: 52 | D48: 57 | E48: 48 | F48: 66 | G48: 70
B50: Net cash ( utilised in) / generated from investing activities | C50: =SUM(C40:C48) -> -938 | D50: =SUM(D40:D48) -> 428 | E50: =SUM(E40:E48) -> -865 | F50: =SUM(F40:F48) -> 176 | G50: =SUM(G40:G48) -> -621 | H50: =SUM(H40:H48) -> -176.52314 | I50: =SUM(I40:I48) -> -228.01079 | J50: =SUM(J40:J48) -> -316.68851 | ... L50: =SUM(L40:L48) -> -545.69464
B52: CASH FLOW FROM FINANCING ACTIVITIES :
B54: Proceeds from issuance of share capital | C54: 6 | D54: 41 | E54: 9 | F54: 34 | G54: 46
B55: (Purchase) / sale of investments by WEOMA trust | C55: -9 | D55: -8 | E55: 4 | F55: 2 | G55: -12
B56: Other borrowings taken | C56: 13 | D56: 0 | E56: 128 | F56: 0 | G56: 0 | H56: ='Debt Schedule'!H25 -> 36.178363 | I56: ='Debt Schedule'!I25 -> 41.520528 | J56: ='Debt Schedule'!J25 -> 48.264626 | K56: ='Debt Schedule'!K25 -> 56.888109 | L56: ='Debt Schedule'!L25 -> 68.068781
B57: Other borrowings (repaid) | C57: 0 | D57: -3 | E57: 0 | F57: -91 | G57: -5 | H57: ='Debt Schedule'!H31 -> -20.301833 | I57: ='Debt Schedule'!I31 -> -21.152289 | J57: ='Debt Schedule'!J31 -> -22.243351 | K57: ='Debt Schedule'!K31 -> -23.637228 | L57: ='Debt Schedule'!L31 -> -25.418373
...

Sheet Ratio Analysis
E2: ARICO LTD
B10: PARTICULARS | C10: 2021 A | D10: 2022 A | E10: 2023A | F10: 2024A | G10: 2025A | H10: 2026 E | I10: 2027 E | J10: 2028 E | K10: 2029 E | L10: 2030 E | M10: TRENDS | N10: Median
B12: GROWTH FACTORS
B13: Revenue Growth (%) | C13: ='Income statement'!C12 -> 0 | D13: ='Income statement'!D12 -> 0.18190855 | E13: ='Income statement'!E12 -> 0.026492851 | F13: ='Income statement'!F12 -> -0.011368292 | G13: ='Income statement'!G12 -> 0.1220346 | H13: ='Income statement'!H12 -> 0.13423806 | I13: ='Income statement'!I12 -> 0.14766187 | J13: ='Income statement'!J12 -> 0.16242805 | ... L13: ='Income statement'!L12 -> 0.19653794 | N13: =MEDIAN(C13:L13) -> 0.14094996
B14: Gross Profit Growth (%) | D14: 0.078877713 | E14: 0.082679097 | F14: 0.11148878 | G14: 0.109684 | H14: 0.065573939 | I14: 0.14896632 | J14: 0.18414021 | K14: 0.19312147 | L14: 0.18635072 | N14: =MEDIAN(C14:L14) -> 0.11148878
B15: EBITDA Growth (%) | D15: =D59/C59-1 -> 0.048938679 | E15: =E59/D59-1 -> 0.098369871 | F15: =F59/E59-1 -> 0.10951894 | G15: =G59/F59-1 -> -0.013376384 | H15: =H59/G59-1 -> 0.11093865 | I15: =I59/H59-1 -> 0.15084568 | J15: =J59/I59-1 -> 0.21533518 | K15: =K59/J59-1 -> 0.21297958 | L15: =L59/K59-1 -> 0.17274735 | N15: =MEDIAN(C15:L15) -> 0.11093865
B16: EBIT Growth (%) | D16: =D58/C58-1 -> 0.06080207 | E16: =E58/D58-1 -> 0.09695122 | F16: =F58/E58-1 -> 0.11728738 | G16: =G58/F58-1 -> -0.024378109 | H16: =H58/G58-1 -> 0.096404406 | I16: =I58/H58-1 -> 0.16640164 | J16: =J58/I58-1 -> 0.23113628 | K16: =K58/J58-1 -> 0.2227773 | L16: =L58/K58-1 -> 0.17635675 | N16: =MEDIAN(C16:L16) -> 0.11728738
B17: Pre-Tax Growth (%) | D17: ='Income statement'!D29/'Income statement'!C29-1 -> 0.060264901 | E17: ='Income statement'!E29/'Income statement'!D29-1 -> 0.088694566 | F17: ='Income statement'!F29/'Income statement'!E29-1 -> 0.11130235 | G17: ='Income statement'!G29/'Income statement'!F29-1 -> -0.014971606 | H17: ='Income statement'!H29/'Income statement'!G29-1 -> 0.096016306 | I17: ='Income statement'!I29/'Income statement'!H29-1 -> 0.16976644 | J17: ='Income statement'!J29/'Income statement'!I29-1 -> 0.23551517 | K17: ='Income statement'!K29/'Income statement'!J29-1 -> 0.22608698 | L17: ='Income statement'!L29/'Income statement'!K29-1 -> 0.17811346 | N17: =MEDIAN(C17:L17) -> 0.11130235
B20: MARGIN
B21: Gross Profit Margin (%) | C21: =('Income statement'!C14-'Income statement'!C21)/'Income statement'!C14 -> 0.4694334 | D21: =('Income statement'!D14-'Income statement'!D21)/'Income statement'!D14 -> 0.42851135 | E21: =('Income statement'!E14-'Income statement'!E21)/'Income statement'!E14 -> 0.45196641 | F21: =('Income statement'!F14-'Income statement'!F21)/'Income statement'!F14 -> 0.50813219 | G21: =('Income statement'!G14-'Income statement'!G21)/'Income statement'!G14 -> 0.50253901 | H21: =('Income statement'!H14-'Income statement'!H21)/'Income statement'!H14 -> 0.47211647 | I21: =('Income statement'!I14-'Income statement'!I21)/'Income statement'!I14 -> 0.47265309 | J21: =('Income statement'!J14-'Income statement'!J21)/'Income statement'!J14 -> 0.48148143 | ... L21: =('Income statement'!L14-'Income statement'!L21)/'Income statement'!L14 -> 0.48323489 | N21: =MEDIAN(C21:L21) -> 0.47706726
B22: EBITDA Margin (%) | C22: =C59/'Income statement'!C14 -> 0.21073559 | D22: =D59/'Income statement'!D14 -> 0.18702691 | E22: =E59/'Income statement'!E14 -> 0.2001229 | F22: =F59/'Income statement'!F14 -> 0.22459339 | G22: =G59/'Income statement'!G14 -> 0.19748869 | H22: =H59/'Income statement'!H14 -> 0.1934319 | I22: =I59/'Income statement'!I14 -> 0.19396851 | J22: =J59/'Income statement'!J14 -> 0.20279686 | ... L22: =L59/'Income statement'!L14 -> 0.20455031 | N22: =MEDIAN(C22:L22) -> 0.20145988
B23: EBIT Margin (%) | C23: =C58/'Income statement'!C14 -> 0.19209742 | D23: =D58/'Income statement'!D14 -> 0.17241379 | E23: =E58/'Income statement'!E14 -> 0.18424826 | F23: =F58/'Income statement'!F14 -> 0.20822542 | G23: =G58/'Income statement'!G14 -> 0.18105438 | H23: =H58/'Income statement'!H14 -> 0.17501513 | I23: =I58/'Income statement'!I14 -> 0.17787289 | J23: =J58/'Income statement'!J14 -> 0.18838652 | ... L23: =L58/'Income statement'!L14 -> 0.19213975 | N23: =MEDIAN(C23:L23) -> 0.18631739
B24: Pre-Tax Margin (%) | C24: ='Income statement'!C29/'Income statement'!C14 -> 0.18762425 | D24: ='Income statement'!D29/'Income statement'!D14 -> 0.16831371 | E24: ='Income statement'!E29/'Income statement'!E14 -> 0.1785129 | F24: ='Income statement'!F29/'Income statement'!F14 -> 0.20066301 | G24: ='Income statement'!G29/'Income statement'!G14 -> 0.17616102 | H24: ='Income statement'!H29/'Income statement'!H14 -> 0.17022471 | I24: ='Income statement'!I29/'Income statement'!I14 -> 0.17350333 | J24: ='Income statement'!J29/'Income statement'!J14 -> 0.18441227 | ... L24: ='Income statement'!L29/'Income statement'!L14 -> 0.18887705 | N24: =MEDIAN(C24:L24) -> 0.18146259
B25: Effective Tax Rate (%) | C25: ='Income statement'!C35/'Income statement'!C31 -> 0.21273802 | D25: ='Income statement'!D35/'Income statement'!D31 -> 0.21611493 | E25: ='Income statement'!E35/'Income statement'!E31 -> 0.24153758 | F25: ='Income statement'!F35/'Income statement'!F31 -> 0.22457408 | G25: ='Income statement'!G35/'Income statement'!G31 -> 0.24004193 | H25: ='Income statement'!H35/'Income statement'!H31 -> 0.29397104 | I25: ='Income statement'!I35/'Income statement'!I31 -> 0.29872021 | J25: ='Income statement'!J35/'Income statement'!J31 -> 0.30332481 | ... L25: ='Income statement'!L35/'Income statement'!L31 -> 0.3024353 | N25: =MEDIAN(C25:L25) -> 0.26775431
B27: LIQUIDITY RATIOS
B28: Current Ratio | C28: ='Balance Sheet'!C45/'Balance Sheet'!C84 -> 1.657228 | D28: ='Balance Sheet'!D45/'Balance Sheet'!D84 -> 1.627961 | E28: ='Balance Sheet'!E45/'Balance Sheet'!E84 -> 1.5726636 | F28: ='Balance Sheet'!F45/'Balance Sheet'!F84 -> 1.6378887 | G28: ='Balance Sheet'!G45/'Balance Sheet'!G84 -> 2.0654206 | H28: ='Balance Sheet'!H45/'Balance Sheet'!H84 -> 2.3617558 | I28: ='Balance Sheet'!I45/'Balance Sheet'!I84 -> 2.9956467 | J28: ='Balance Sheet'!J45/'Balance Sheet'!J84 -> 3.2291354 | ... L28: ='Balance Sheet'!L45/'Balance Sheet'!L84 -> 3.155898 | N28: =MEDIAN(C28:L28) -> 2.2135882
B29: Quick Ratio | C29: =('Balance Sheet'!C45-'Balance Sheet'!C34)/'Balance Sheet'!C84 -> 1.0978639 | D29: =('Balance Sheet'!D45-'Balance Sheet'!D34)/'Balance Sheet'!D84 -> 0.97213191 | E29: =('Balance Sheet'!E45-'Balance Sheet'!E34)/'Balance Sheet'!E84 -> 1.0683409 | F29: =('Balance Sheet'!F45-'Balance Sheet'!F34)/'Balance Sheet'!F84 -> 1.0912439 | G29: =('Balance Sheet'!G45-'Balance Sheet'!G34)/'Balance Sheet'!G84 -> 1.563592 | H29: =('Balance Sheet'!H45-'Balance Sheet'!H34)/'Balance Sheet'!H84 -> 1.7116819 | I29: =('Balance Sheet'!I45-'Balance Sheet'!I34)/'Balance Sheet'!I84 -> 2.4061161 | J29: =('Balance Sheet'!J45-'Balance Sheet'!J34)/'Balance Sheet'!J84 -> 2.532512 | ... L29: =('Balance Sheet'!L45-'Balance Sheet'!L34)/'Balance Sheet'!L84 -> 2.3988106 | N29: =MEDIAN(C29:L29) -> 1.637637
B31: TURNOVER RATIO
B32: Receivable Turnover Ratio | C32: ='Working Capital Schedule'!C33 -> 0 | D32: ='Working Capital Schedule'!D33 -> 18.292308 | E32: ='Working Capital Schedule'!E33 -> 11.714457 | F32: ='Working Capital Schedule'!F33 -> 9.2639155 | G32: ='Working Capital Schedule'!G33 -> 9.257265 | H32: ='Working Capital Schedule'!H33 -> 12.131986 | I32: ='Working Capital Schedule'!I33 -> 10.591906 | J32: ='Working Capital Schedule'!J33 -> 10.311268 | ... L32: ='Working Capital Schedule'!L33 -> 10.902067 | N32: =MEDIAN(C32:L32) -> 10.582506
B33: Payable Turnover Ratio | C33: ='Working Capital Schedule'!C45 -> 0 | D33: ='Working Capital Schedule'!D45 -> 0.39628733 | E33: ='Working Capital Schedule'!E45 -> 0.3869814 | F33: ='Working Capital Schedule'!F45 -> 0.49587867 | G33: ='Working Capital Schedule'!G45 -> 0.65217391 | H33: ='Working Capital Schedule'!H45 -> 0.48283033 | I33: ='Working Capital Schedule'!I45 -> 0.48283033 | J33: ='Working Capital Schedule'!J45 -> 0.48283033 | ... L33: ='Working Capital Schedule'!L45 -> 0.48283033 | N33: =MEDIAN(C33:L33) -> 0.48283033
B34: Inventory Turnover Ratio | C34: ='Working Capital Schedule'!C21 -> 0 | D34: ='Working Capital Schedule'!D21 -> 4.2836879 | E34: ='Working Capital Schedule'!E21 -> 4.0583997 | F34: ='Working Capital Schedule'!F21 -> 3.7079266 | G34: ='Working Capital Schedule'!G21 -> 4.1913652 | H34: ='Working Capital Schedule'!H21 -> 4.0603449 | I34: ='Working Capital Schedule'!I21 -> 4.0045091 | J34: ='Working Capital Schedule'!J21 -> 3.9910364 | ... L34: ='Working Capital Schedule'!L21 -> 4.0294261 | N34: =MEDIAN(C34:L34) -> 4.0439129
B35: Fixed Asset Turnover Ratio | C35: ='Income statement'!C14/'Balance Sheet'!C47 -> 1.4606171 | D35: ='Income statement'!D14/'Balance Sheet'!D47 -> 1.6439682 | E35: ='Income statement'!E14/'Balance Sheet'!E47 -> 1.4057011 | F35: ='Income statement'!F14/'Balance Sheet'!F47 -> 1.3007681 | G35: ='Income statement'!G14/'Balance Sheet'!G47 -> 1.2989926 | H35: ='Income statement'!H14/'Balance Sheet'!H47 -> 1.1899871 | I35: ='Income statement'!I14/'Balance Sheet'!I47 -> 1.1633537 | J35: ='Income statement'!J14/'Balance Sheet'!J47 -> 1.1001996 | ... L35: ='Income statement'!L14/'Balance Sheet'!L47 -> 1.2466195 | N35: =MEDIAN(C35:L35) -> 1.272806
B39: Receivable days | C39: ='Working Capital Schedule'!C35 -> 0 | D39: ='Working Capital Schedule'!D35 -> 19.953743 | E39: ='Working Capital Schedule'!E35 -> 31.158081 | F39: ='Working Capital Schedule'!F35 -> 39.400186 | G39: ='Working Capital Schedule'!G35 -> 39.428492 | H39: ='Working Capital Schedule'!H35 -> 30.085758 | I39: ='Working Capital Schedule'!I35 -> 34.460276 | J39: ='Working Capital Schedule'!J35 -> 35.398168 | ... L39: ='Working Capital Schedule'!L35 -> 33.47989 | N39: =MEDIAN(C39:L39) -> 33.970083
B40: Payable Days | C40: ='Working Capital Schedule'!C47 -> 0 | D40: ='Working Capital Schedule'!D47 -> 921.04888 | E40: ='Working Capital Schedule'!E47 -> 943.19778 | F40: ='Working Capital Schedule'!F47 -> 736.06715 | G40: ='Working Capital Schedule'!G47 -> 559.66667 | H40: ='Working Capital Schedule'!H47 -> 755.95914 | I40: ='Working Capital Schedule'!I47 -> 755.95914 | J40: ='Working Capital Schedule'!J47 -> 755.95914 | ... L40: ='Working Capital Schedule'!L47 -> 755.95914 | N40: =MEDIAN(C40:L40) -> 755.95914
B41: Inventory Days | C41: ='Working Capital Schedule'!C23 -> 0 | D41: ='Working Capital Schedule'!D23 -> 85.206954 | E41: ='Working Capital Schedule'!E23 -> 89.936928 | F41: ='Working Capital Schedule'!F23 -> 98.437763 | G41: ='Working Capital Schedule'!G23 -> 87.083797 | H41: ='Working Capital Schedule'!H23 -> 89.893842 | I41: ='Working Capital Schedule'!I23 -> 91.147252 | J41: ='Working Capital Schedule'!J23 -> 91.45494 | ... L41: ='Working Capital Schedule'!L23 -> 90.58362 | N41: =MEDIAN(C41:L41) -> 89.915385
B42: Cash Conversion Cycle | C42: =C41+C39-C40 -> 0 | D42: =D41+D39-D40 -> -815.88818 | E42: =E41+E39-E40 -> -822.10277 | F42: =F41+F39-F40 -> -598.2292 | G42: =G41+G39-G40 -> -433.15438 | H42: =H41+H39-H40 -> -635.97954 | I42: =I41+I39-I40 -> -630.35161 | J42: =J41+J39-J40 -> -629.10603 | ... L42: =L41+L39-L40 -> -631.89563 | N42: =MEDIAN(C42:L42) -> -630.96394
B45: CFO%Sales | C45: ='Cashflow statement'!C36/'Income statement'!C14 -> 0.23782306 | D45: ='Cashflow statement'!D36/'Income statement'!D14 -> 0.10618167 | E45: ='Cashflow statement'!E36/'Income statement'!E14 -> 0.1442032 | F45: ='Cashflow statement'!F36/'Income statement'!F14 -> 0.16222936 | G45: ='Cashflow statement'!G36/'Income statement'!G14 -> 0.10396085 | H45: ='Cashflow statement'!H36/'Income statement'!H14 -> 0.20400522 | I45: ='Cashflow statement'!I36/'Income statement'!I14 -> 0.20522228 | J45: ='Cashflow statement'!J36/'Income statement'!J14 -> 0.19001825 | ... L45: ='Cashflow statement'!L36/'Income statement'!L14 -> 0.2155596 | N45: =MEDIAN(C45:L45) -> 0.19701174
B46: CFO%Totak Assets | C46: ='Cashflow statement'!C36/'Balance Sheet'!C47 -> 0.34736842 | D46: ='Cashflow statement'!D36/'Balance Sheet'!D47 -> 0.17455928 | E46: ='Cashflow statement'!E36/'Balance Sheet'!E47 -> 0.20270659 | F46: ='Cashflow statement'!F36/'Balance Sheet'!F47 -> 0.21102277 | G46: ='Cashflow statement'!G36/'Balance Sheet'!G47 -> 0.13504438 | H46: ='Cashflow statement'!H36/'Balance Sheet'!H47 -> 0.24276358 | I46: ='Cashflow statement'!I36/'Balance Sheet'!I47 -> 0.2387461 | J46: ='Cashflow statement'!J36/'Balance Sheet'!J47 -> 0.20905801 | ... L46: ='Cashflow statement'!L36/'Balance Sheet'!L47 -> 0.26872079 | N46: =MEDIAN(C46:L46) -> 0.21668635
B47: CFO%Total Debt | C47: ='Cashflow statement'!C36/('Balance Sheet'!C69+'Balance Sheet'!C84) -> 0.84991119 | D47: ='Cashflow statement'!D36/('Balance Sheet'!D69+'Balance Sheet'!D84) -> 0.42419152 | E47: ='Cashflow statement'!E36/('Balance Sheet'!E69+'Balance Sheet'!E84) -> 0.47090301 | F47: ='Cashflow statement'!F36/('Balance Sheet'!F69+'Balance Sheet'!F84) -> 0.48154982 | G47: ='Cashflow statement'!G36/('Balance Sheet'!G69+'Balance Sheet'!G84) -> 0.27652259 | H47: ='Cashflow statement'!H36/('Balance Sheet'!H69+'Balance Sheet'!H84) -> 0.54188008 | I47: ='Cashflow statement'!I36/('Balance Sheet'!I69+'Balance Sheet'!I84) -> 0.63088632 | J47: ='Cashflow statement'!J36/('Balance Sheet'!J69+'Balance Sheet'!J84) -> 0.59816864 | ... L47: ='Cashflow statement'!L36/('Balance Sheet'!L69+'Balance Sheet'!L84) -> 0.7896448 | N47: =MEDIAN(C47:L47) -> 0.57002436
B50: Return on Capital employed | D50: =D58/D57 -> 1.2261682 | E50: =E58/E57 -> 1.3117025 | F50: =F58/F57 -> 1.3627119 | G50: =G58/G57 -> 0.9380531 | H50: =H58/H57 -> 0.63929436 | I50: =I58/I57 -> 0.49947046 | J50: =J58/J57 -> 0.44258815 | K50: =K58/K57 -> 0.40043356 | L50: =L58/L57 -> 0.4235334 | N50: =MEDIAN(C50:L50) -> 0.63929436
B51: Retained Earnings Percentage | C51: =('Income statement'!C36-('Cashflow statement'!C63))/'Income statement'!C36 -> 1.8073394 | D51: =('Income statement'!D36-('Cashflow statement'!D63))/'Income statement'!D36 -> 1.9521912 | E51: =('Income statement'!E36-('Cashflow statement'!E63))/'Income statement'!E36 -> 1.4402421 | F51: =('Income statement'!F36-('Cashflow statement'!F63))/'Income statement'!F36 -> 1.8182423 | G51: =('Income statement'!G36-('Cashflow statement'!G63))/'Income statement'!G36 -> 1.3124138 | H51: =('Income statement'!H36-('Cashflow statement'!H63))/'Income statement'!H36 -> 1.3068176 | I51: =('Income statement'!I36-('Cashflow statement'!I63))/'Income statement'!I36 -> 1.2640659 | J51: =('Income statement'!J36-('Cashflow statement'!J63))/'Income statement'!J36 -> 1.215142 | ... L51: =('Income statement'!L36-('Cashflow statement'!L63))/'Income statement'!L36 -> 1.148752 | N51: =MEDIAN(C51:L51) -> 1.3096157
B52: Return on Equity | C52: ='Income statement'!C36/AVERAGE('Balance Sheet'!C56,'Balance Sheet'!D56) -> 0.36399514 | D52: ='Income statement'!D36/AVERAGE('Balance Sheet'!D56,'Balance Sheet'!E56) -> 0.35119631 | E52: ='Income statement'!E36/AVERAGE('Balance Sheet'!E56,'Balance Sheet'!F56) -> 0.34648146 | F52: ='Income statement'!F36/AVERAGE('Balance Sheet'!F56,'Balance Sheet'!G56) -> 0.38478289 | G52: ='Income statement'!G36/AVERAGE('Balance Sheet'!G56,'Balance Sheet'!H56) -> 0.31482452 | H52: ='Income statement'!H36/AVERAGE('Balance Sheet'!H56,'Balance Sheet'!I56) -> 0.24352667 | I52: ='Income statement'!I36/AVERAGE('Balance Sheet'!I56,'Balance Sheet'!J56) -> 0.21554002 | J52: ='Income statement'!J36/AVERAGE('Balance Sheet'!J56,'Balance Sheet'!K56) -> 0.20392922 | ... L52: ='Income statement'!L36/AVERAGE('Balance Sheet'!L56,'Balance Sheet'!M56) -> 0.27267815 | N52: =MEDIAN(C52:L52) -> 0.29375134
B53: Interest Coverage Ratio | C53: =C58/'Income statement'!C23 -> 45.470588 | D53: =D58/'Income statement'!D23 -> 42.051282 | E53: =E58/'Income statement'!E23 -> 32.125 | F53: =F58/'Income statement'!F23 -> 27.534247 | G53: =G58/'Income statement'!G23 -> 37 | H53: =H58/'Income statement'!H23 -> 36.534438 | I53: =I58/'Income statement'!I23 -> 40.707289 | J53: =J58/'Income statement'!J23 -> 47.401874 | ... L53: =L58/'Income statement'!L23 -> 58.889974 | N53: =MEDIAN(C53:L53) -> 41.379286
B56: CAPITAL EMPLOYED | C56: ='Balance Sheet'!C45-'Balance Sheet'!C84 -> 1323 | D56: ='Balance Sheet'!D45-'Balance Sheet'!D84 -> 1352 | E56: ='Balance Sheet'!E45-'Balance Sheet'!E84 -> 1391 | F56: ='Balance Sheet'!F45-'Balance Sheet'!F84 -> 1559 | G56: ='Balance Sheet'!G45-'Balance Sheet'!G84 -> 2622 | H56: ='Balance Sheet'!H45-'Balance Sheet'!H84 -> 4104.3194 | I56: ='Balance Sheet'!I45-'Balance Sheet'!I84 -> 5937.5986 | J56: ='Balance Sheet'!J45-'Balance Sheet'!J84 -> 8014.2847 | ... L56: ='Balance Sheet'!L45-'Balance Sheet'!L84 -> 10129.878
B57: AVERAGE CAPITALL EMPLYOED | D57: =AVERAGE(C56:D56) -> 1337.5 | E57: =AVERAGE(D56:E56) -> 1371.5 | F57: =AVERAGE(E56:F56) -> 1475 | G57: =AVERAGE(F56:G56) -> 2090.5 | H57: =AVERAGE(G56:H56) -> 3363.1597 | I57: =AVERAGE(H56:I56) -> 5020.959 | J57: =AVERAGE(I56:J56) -> 6975.9416 | K57: =AVERAGE(J56:K56) -> 9427.9989 | L57: =AVERAGE(K56:L56) -> 10485.795
B58: EBIT | C58: ='Income statement'!C27+'Income statement'!C23 -> 1546 | D58: ='Income statement'!D27+'Income statement'!D23 -> 1640 | E58: ='Income statement'!E27+'Income statement'!E23 -> 1799 | F58: ='Income statement'!F27+'Income statement'!F23 -> 2010 | G58: ='Income statement'!G27+'Income statement'!G23 -> 1961 | H58: ='Income statement'!H27+'Income statement'!H23 -> 2150.049 | I58: ='Income statement'!I27+'Income statement'!I23 -> 2507.8207 | J58: ='Income statement'!J27+'Income statement'!J23 -> 3087.4691 | ... L58: ='Income statement'!L27+'Income statement'!L23 -> 4441.0845
B59: EBITDA | C59: ='Income statement'!C23+'Income statement'!C24+'Income statement'!C31 -> 1696 | D59: ='Income statement'!D23+'Income statement'!D24+'Income statement'!D31 -> 1779 | E59: ='Income statement'!E23+'Income statement'!E24+'Income statement'!E31 -> 1954 | F59: ='Income statement'!F23+'Income statement'!F24+'Income statement'!F31 -> 2168 | G59: ='Income statement'!G23+'Income statement'!G24+'Income statement'!G31 -> 2139 | H59: ='Income statement'!H23+'Income statement'!H24+'Income statement'!H31 -> 2376.2978 | I59: ='Income statement'!I23+'Income statement'!I24+'Income statement'!I31 -> 2734.752 | J59: ='Income statement'!J23+'Income statement'!J24+'Income statement'!J31 -> 3323.6404 | ... L59: ='Income statement'!L23+'Income statement'!L24+'Income statement'!L31 -> 4727.9402

Sheet Assumption sheet
E2: ARICO LTD
B10: PARTICULARS | C10: 2021 A | D10: 2022 A | E10: 2023A | F10: 2024A | G10: 2025A | H10: 2026 E | I10: 2027 E | J10: 2028 E | K10: 2029 E | L10: 2030 E
B13: Revenue Schedule(%)
B14: % change in Revenue | C14: ='Revenue schedule'!C13 -> 0 | D14: ='Revenue schedule'!D13 -> 0.18190855 | E14: ='Revenue schedule'!E13 -> 0.026492851 | F14: ='Revenue schedule'!F13 -> -0.011368292 | G14: ='Revenue schedule'!G13 -> 0.1220346 | H14: ='Revenue schedule'!H13 -> 0.13423806 | I14: ='Revenue schedule'!I13 -> 0.14766187 | J14: ='Revenue schedule'!J13 -> 0.16242805 | ... L14: ='Revenue schedule'!L13 -> 0.19653794
B16: Cost Schedule (%)
B17: COGS | C17: ='Cost Schedule'!C20 -> 0.5305666 | D17: ='Cost Schedule'!D20 -> 0.57148865 | E17: ='Cost Schedule'!E20 -> 0.54803359 | F17: ='Cost Schedule'!F20 -> 0.49186781 | G17: ='Cost Schedule'!G20 -> 0.49746099 | H17: ='Cost Schedule'!H20 -> 0.52788353 | I17: ='Cost Schedule'!I20 -> 0.52734691 | J17: ='Cost Schedule'!J20 -> 0.51851857 | ... L17: ='Cost Schedule'!L20 -> 0.51676511
B19: Employee Expense | C19: ='Cost Schedule'!C31 -> 0.07082505 | D19: ='Cost Schedule'!D31 -> 0.061606392 | E19: ='Cost Schedule'!E31 -> 0.066878329 | F19: ='Cost Schedule'!F31 -> 0.07697089 | G19: ='Cost Schedule'!G31 -> 0.076724218 | H19: ='Cost Schedule'!H31 -> 0.070600976 | I19: ='Cost Schedule'!I31 -> 0.070600976 | J19: ='Cost Schedule'!J31 -> 0.070600976 | ... L19: ='Cost Schedule'!L31 -> 0.070600976
B21: Tax Expense | C21: ='Cost Schedule'!C41 -> 0.27022519 | D21: ='Cost Schedule'!D41 -> 0.27569721 | E21: ='Cost Schedule'!E41 -> 0.31845688 | F21: ='Cost Schedule'!F41 -> 0.28961385 | G21: ='Cost Schedule'!G41 -> 0.31586207 | H21: ='Cost Schedule'!H41 -> 0.29397104 | I21: ='Cost Schedule'!I41 -> 0.29872021 | J21: ='Cost Schedule'!J41 -> 0.30332481 | ... L21: ='Cost Schedule'!L41 -> 0.3024353
B23: Other Expenses | C23: ='Cost Schedule'!C36 -> 0.20091948 | D23: ='Cost Schedule'!D36 -> 0.19018082 | E23: ='Cost Schedule'!E36 -> 0.19971323 | F23: ='Cost Schedule'!F36 -> 0.22127836 | G23: ='Cost Schedule'!G36 -> 0.2283261 | H23: ='Cost Schedule'!H36 -> 0.2080836 | I23: ='Cost Schedule'!I36 -> 0.2080836 | J23: ='Cost Schedule'!J36 -> 0.2080836 | ... L23: ='Cost Schedule'!L36 -> 0.2080836
B25: Asset Schedule (%)
B26: Addition | C26: ='Asset Schedule'!C25 -> 7.8670577 | D26: ='Asset Schedule'!D25 -> 8.7749077 | E26: ='Asset Schedule'!E25 -> 7.5223421 | F26: ='Asset Schedule'!F25 -> 5.7526818 | G26: ='Asset Schedule'!G25 -> 5.6323453 | H26: ='Asset Schedule'!H25 -> 7.1098669 | I26: ='Asset Schedule'!I25 -> 6.9584288 | J26: ='Asset Schedule'!J25 -> 6.595133 | ... L26: ='Asset Schedule'!L25 -> 6.541093
B28: Disposal | C28: ='Asset Schedule'!C30 -> 0 | D28: ='Asset Schedule'!D30 -> -0.0029325513 | E28: ='Asset Schedule'!E30 -> -0.021834061 | F28: ='Asset Schedule'!F30 -> -0.012405238 | G28: ='Asset Schedule'!G30 -> -0.020472441 | H28: ='Asset Schedule'!H30 -> -0.014411073 | I28: ='Asset Schedule'!I30 -> -0.017280703 | J28: ='Asset Schedule'!J30 -> -0.016142364 | ... L28: ='Asset Schedule'!L30 -> -0.016227696
B30: Depreciation | C30: ='Asset Schedule'!C35 -> 0 | D30: ='Asset Schedule'!D35 -> -0.24069264 | E30: ='Asset Schedule'!E35 -> -0.23360965 | F30: ='Asset Schedule'!F35 -> -0.19700748 | G30: ='Asset Schedule'!G35 -> -0.17231365 | H30: ='Asset Schedule'!H35 -> -0.21090585 | I30: ='Asset Schedule'!I35 -> -0.21090585 | J30: ='Asset Schedule'!J35 -> -0.21090585 | ... L30: ='Asset Schedule'!L35 -> -0.21090585
B32: Debt Schedule (%)
B33: New Borrowings | C33: ='Debt Schedule'!C27 -> 0.0016153082 | D33: ='Debt Schedule'!D27 -> 0 | E33: ='Debt Schedule'!E27 -> 0.013109381 | F33: ='Debt Schedule'!F27 -> 0 | G33: ='Debt Schedule'!G27 -> 0 | H33: ='Debt Schedule'!H27 -> 0.0029449379 | I33: ='Debt Schedule'!I27 -> 0.0029449379 | J33: ='Debt Schedule'!J27 -> 0.0029449379 | ... L33: ='Debt Schedule'!L27 -> 0.0029449379
B35: Repayment | C35: ='Debt Schedule'!C33 -> 0 | D35: ='Debt Schedule'!D33 -> -0.0088235294 | E35: ='Debt Schedule'!E33 -> 0 | F35: ='Debt Schedule'!F33 -> -0.19238901 | G35: ='Debt Schedule'!G33 -> -0.01305483 | H35: ='Debt Schedule'!H33 -> -0.053566842 | I35: ='Debt Schedule'!I33 -> -0.053566842 | J35: ='Debt Schedule'!J33 -> -0.053566842 | ... L35: ='Debt Schedule'!L33 -> -0.053566842
B37: Finance cost | C37: ='Debt Schedule'!C39 -> 0.2 | D37: ='Debt Schedule'!D39 -> 0.11386861 | E37: ='Debt Schedule'!E39 -> 0.13691932 | F37: ='Debt Schedule'!F39 -> 0.17056075 | G37: ='Debt Schedule'!G39 -> 0.13910761 | H37: ='Debt Schedule'!H39 -> 0.15209126 | I37: ='Debt Schedule'!I39 -> 0.15209126 | J37: ='Debt Schedule'!J39 -> 0.15209126 | ... L37: ='Debt Schedule'!L39 -> 0.15209126
B39: Working Capital Schedule (%)
B40: Inventory Turnover Ratio | C40: ='Working Capital Schedule'!C21 -> 0 | D40: ='Working Capital Schedule'!D21 -> 4.2836879 | E40: ='Working Capital Schedule'!E21 -> 4.0583997 | F40: ='Working Capital Schedule'!F21 -> 3.7079266 | G40: ='Working Capital Schedule'!G21 -> 4.1913652 | H40: ='Working Capital Schedule'!H21 -> 4.0603449 | I40: ='Working Capital Schedule'!I21 -> 4.0045091 | J40: ='Working Capital Schedule'!J21 -> 3.9910364 | ... L40: ='Working Capital Schedule'!L21 -> 4.0294261
B42: Receivable Turnover Ratio | C42: ='Working Capital Schedule'!C33 -> 0 | D42: ='Working Capital Schedule'!D33 -> 18.292308 | E42: ='Working Capital Schedule'!E33 -> 11.714457 | F42: ='Working Capital Schedule'!F33 -> 9.2639155 | G42: ='Working Capital Schedule'!G33 -> 9.257265 | H42: ='Working Capital Schedule'!H33 -> 12.131986 | I42: ='Working Capital Schedule'!I33 -> 10.591906 | J42: ='Working Capital Schedule'!J33 -> 10.311268 | ... L42: ='Working Capital Schedule'!L33 -> 10.902067
B44: Payable Turnover Ratio | C44: ='Working Capital Schedule'!C45 -> 0 | D44: ='Working Capital Schedule'!D45 -> 0.39628733 | E44: ='Working Capital Schedule'!E45 -> 0.3869814 | F44: ='Working Capital Schedule'!F45 -> 0.49587867 | G44: ='Working Capital Schedule'!G45 -> 0.65217391 | H44: ='Working Capital Schedule'!H45 -> 0.48283033 | I44: ='Working Capital Schedule'!I45 -> 0.48283033 | J44: ='Working Capital Schedule'!J45 -> 0.48283033 | ... L44: ='Working Capital Schedule'!L45 -> 0.48283033

Sheet Revenue schedule
E2: ARICO LTD
B10: PARTICULARS | C10: 2021 A | D10: 2022 A | E10: 2023A | F10: 2024A | G10: 2025A | H10: 2026 E | I10: 2027 E | J10: 2028 E | K10: 2029 E | L10: 2030 E
B13: % change in revenue | D13: =D15/C15-1 -> 0.18190855 | E13: =E15/D15-1 -> 0.026492851 | F13: =F15/E15-1 -> -0.011368292 | G13: =G15/F15-1 -> 0.1220346 | H13: =G13+G13*10% -> 0.13423806 | I13: =H13+H13*10% -> 0.14766187 | J13: =I13+I13*10% -> 0.16242805 | K13: =J13+J13*10% -> 0.17867086 | L13: =K13+K13*10% -> 0.19653794
B15: Revenue from operations | C15: ='Income statement'!C14 -> 8048 | D15: ='Income statement'!D14 -> 9512 | E15: ='Income statement'!E14 -> 9764 | F15: ='Income statement'!F14 -> 9653 | G15: ='Income statement'!G14 -> 10831 | H15: =G15*(1+H13) -> 12284.932 | I15: =H15*(1+I13) -> 14098.948 | J15: =I15*(1+J13) -> 16389.013 | K15: =J15*(1+K13) -> 19317.252 | L15: =K15*(1+L13) -> 23113.825

Sheet Cost Schedule
E2: ARICO LTD
B10: PARTICULARS | C10: 2021 A | D10: 2022 A | E10: 2023A | F10: 2024A | G10: 2025A | H10: 2026 E | I10: 2027 E | J10: 2028 E | K10: 2029 E | L10: 2030 E
B12: Revenue from operations | C12: ='Income statement'!C14 -> 8048 | D12: ='Income statement'!D14 -> 9512 | E12: ='Income statement'!E14 -> 9764 | F12: ='Income statement'!F14 -> 9653 | G12: ='Income statement'!G14 -> 10831 | H12: ='Income statement'!H14 -> 12284.932 | I12: ='Income statement'!I14 -> 14098.948 | J12: ='Income statement'!J14 -> 16389.013 | ... L12: ='Income statement'!L14 -> 23113.825
B14: COGS :
B15: Cost of material consumed | C15: ='Income statement'!C18 -> 3884 | D15: ='Income statement'!D18 -> 5061 | E15: ='Income statement'!E18 -> 4649 | F15: ='Income statement'!F18 -> 3941 | G15: ='Income statement'!G18 -> 4572 | H15: =H18*H23 -> 5691.2646 | I15: =I18*I23 -> 6525.0077 | J15: =J18*J23 -> 7457.8735 | K15: =K18*K23 -> 8690.3053 | L15: =L18*L23 -> 10482.453
B16: Purchases of stock in trade | C16: ='Income statement'!C19 -> 339 | D16: ='Income statement'!D19 -> 491 | E16: ='Income statement'!E19 -> 541 | F16: ='Income statement'!F19 -> 752 | G16: ='Income statement'!G19 -> 960 | H16: =H18*H24 -> 787.76528 | I16: =I18*I24 -> 903.16913 | J16: =J18*J24 -> 1032.2932 | K16: =K18*K24 -> 1202.8822 | L16: =L18*L24 -> 1450.9451
B17: Changes in inventories of finished goods , stock in trade and work in progress | C17: ='Income statement'!C20 -> 47 | D17: ='Income statement'!D20 -> -116 | E17: ='Income statement'!E20 -> 161 | F17: ='Income statement'!F20 -> 55 | G17: ='Income statement'!G20 -> -144 | H17: =H18*H25 -> 5.9836009 | I17: =I18*I25 -> 6.8601698 | J17: =J18*J25 -> 7.840953 | K17: =K18*K25 -> 9.1366897 | L17: =L18*L25 -> 11.020892
B18: Total | C18: ='Income statement'!C21 -> 4270 | D18: ='Income statement'!D21 -> 5436 | E18: ='Income statement'!E21 -> 5351 | F18: ='Income statement'!F21 -> 4748 | G18: ='Income statement'!G21 -> 5388 | H18: =H12*H20 -> 6485.0135 | I18: =I12*I20 -> 7435.037 | J18: =J12*J20 -> 8498.0077 | K18: =K12*K20 -> 9902.3242 | L18: =L12*L20 -> 11944.419
B20: Total as a (%) of revenue | C20: =C18/C12 -> 0.5305666 | D20: =D18/D12 -> 0.57148865 | E20: =E18/E12 -> 0.54803359 | F20: =F18/F12 -> 0.49186781 | G20: =G18/G12 -> 0.49746099 | H20: =AVERAGE(C20:G20) -> 0.52788353 | I20: =AVERAGE(D20:H20) -> 0.52734691 | J20: =AVERAGE(E20:I20) -> 0.51851857 | K20: =AVERAGE(F20:J20) -> 0.51261556 | L20: =AVERAGE(G20:K20) -> 0.51676511
B22: COGS (%)
B23: Cost of material consumed | C23: =C15/C18 -> 0.90960187 | D23: =D15/D18 -> 0.93101545 | E23: =E15/E18 -> 0.86880957 | F23: =F15/F18 -> 0.8300337 | G23: =G15/G18 -> 0.84855234 | H23: =AVERAGE(C23:G23) -> 0.87760259 | I23: 0.87760259 | J23: 0.87760259 | K23: 0.87760259 | L23: 0.87760259
B24: Purchases of stock in trade | C24: =C16/C18 -> 0.079391101 | D24: =D16/D18 -> 0.090323767 | E24: =E16/E18 -> 0.1011026 | F24: =F16/F18 -> 0.15838248 | G24: =G16/G18 -> 0.17817372 | H24: =AVERAGE(C24:G24) -> 0.12147473 | I24: 0.12147473 | J24: 0.12147473 | K24: 0.12147473 | L24: 0.12147473
B25: Changes in inventories of finished goods , stock in trade and work in progress | C25: =C17/C18 -> 0.011007026 | D25: =D17/D18 -> -0.02133922 | E25: =E17/E18 -> 0.030087834 | F25: =F17/F18 -> 0.011583825 | G25: =G17/G18 -> -0.026726058 | H25: =AVERAGE(C25:G25) -> 0.00092268133 | I25: 0.00092268133 | J25: 0.00092268133 | K25: 0.00092268133 | L25: 0.00092268133
B26: Total | C26: =SUM(C23:C25) -> 1 | D26: =SUM(D23:D25) -> 1 | E26: =SUM(E23:E25) -> 1 | F26: =SUM(F23:F25) -> 1 | G26: =SUM(G23:G25) -> 1 | H26: =SUM(H23:H25) -> 1 | I26: =SUM(I23:I25) -> 1 | J26: =SUM(J23:J25) -> 1 | ... L26: =SUM(L23:L25) -> 1
B28: Employee benefit cost :
B29: Emplyoee benefit cost | C29: ='Income statement'!C22 -> 570 | D29: ='Income statement'!D22 -> 586 | E29: ='Income statement'!E22 -> 653 | F29: ='Income statement'!F22 -> 743 | G29: ='Income statement'!G22 -> 831 | H29: =H12*H31 -> 867.32821 | I29: =I12*I31 -> 995.39952 | J29: =J12*J31 -> 1157.0803 | K29: =K12*K31 -> 1363.8169 | L29: =L12*L31 -> 1631.8586
B31: Employee benefit cost as a (%) of revenue | C31: =C29/C12 -> 0.07082505 | D31: =D29/D12 -> 0.061606392 | E31: =E29/E12 -> 0.066878329 | F31: =F29/F12 -> 0.07697089 | G31: =G29/G12 -> 0.076724218 | H31: =AVERAGE(C31:G31) -> 0.070600976 | I31: 0.070600976 | J31: 0.070600976 | K31: 0.070600976 | L31: 0.070600976
B33: Other expenses :
B34: Other expenses | C34: ='Income statement'!C25 -> 1617 | D34: ='Income statement'!D25 -> 1809 | E34: ='Income statement'!E25 -> 1950 | F34: ='Income statement'!F25 -> 2136 | G34: ='Income statement'!G25 -> 2473 | H34: =H12*H36 -> 2556.293 | I34: =I12*I36 -> 2933.76 | J34: =J12*J36 -> 3410.2849 | K34: =K12*K36 -> 4019.6034 | L34: =L12*L36 -> 4809.608
B36: Other expenses as a (%) of revenue | C36: =C34/C12 -> 0.20091948 | D36: =D34/D12 -> 0.19018082 | E36: =E34/E12 -> 0.19971323 | F36: =F34/F12 -> 0.22127836 | G36: =G34/G12 -> 0.2283261 | H36: =AVERAGE(C36:G36) -> 0.2080836 | I36: 0.2080836 | J36: 0.2080836 | K36: 0.2080836 | L36: 0.2080836
B38: Tax Expenses
B39: Tax Expenses | C39: ='Income statement'!C35 -> 324 | D39: ='Income statement'!D35 -> 346 | E39: ='Income statement'!E35 -> 421 | F39: ='Income statement'!F35 -> 435 | G39: ='Income statement'!G35 -> 458 | H39: ='Income statement'!H31*'Cost Schedule'!H41 -> 614.75198 | I39: ='Income statement'!I31*'Cost Schedule'!I41 -> 730.73373 | J39: ='Income statement'!J31*'Cost Schedule'!J41 -> 916.74925 | K39: ='Income statement'!K31*'Cost Schedule'!K41 -> 1112.7995 | L39: ='Income statement'!L31*'Cost Schedule'!L41 -> 1320.3331
B41: Tax Expense as a (%) of profit before tax | C41: =C39/'Income statement'!C36 -> 0.27022519 | D41: =D39/'Income statement'!D36 -> 0.27569721 | E41: =E39/'Income statement'!E36 -> 0.31845688 | F41: =F39/'Income statement'!F36 -> 0.28961385 | G41: =G39/'Income statement'!G36 -> 0.31586207 | H41: =AVERAGE(C41:G41) -> 0.29397104 | I41: =AVERAGE(D41:H41) -> 0.29872021 | J41: =AVERAGE(E41:I41) -> 0.30332481 | K41: =AVERAGE(F41:J41) -> 0.3002984 | L41: =AVERAGE(G41:K41) -> 0.3024353
B44: Current tax | C44: ='Income statement'!C33 -> 335 | D44: ='Income statement'!D33 -> 343 | E44: ='Income statement'!E33 -> 377 | F44: ='Income statement'!F33 -> 353 | G44: ='Income statement'!G33 -> 480 | H44: =H46*H48 -> 587.73931 | I44: =I46*I48 -> 698.62473 | J44: =J46*J48 -> 876.4666 | K44: =K46*K48 -> 1063.9023 | L44: =L46*L48 -> 1262.3167
B45: Deferred tax | C45: ='Income statement'!C34 -> -11 | D45: ='Income statement'!D34 -> 3 | E45: ='Income statement'!E34 -> 44 | F45: ='Income statement'!F34 -> 82 | G45: ='Income statement'!G34 -> -22 | H45: =H46*H49 -> 27.012667 | I45: =I46*I49 -> 32.108992 | J45: =J46*J49 -> 40.282655 | K45: =K46*K49 -> 48.897251 | L45: =L46*L49 -> 58.016435
B46: Total Tax | C46: =SUM(C44:C45) -> 324 | D46: =SUM(D44:D45) -> 346 | E46: =SUM(E44:E45) -> 421 | F46: =SUM(F44:F45) -> 435 | G46: =SUM(G44:G45) -> 458 | H46: =H39 -> 614.75198 | I46: =I39 -> 730.73373 | J46: =J39 -> 916.74925 | K46: =K39 -> 1112.7995 | L46: =L39 -> 1320.3331
B48: Current tax | C48: =C44/C46 -> 1.0339506 | D48: =D44/D46 -> 0.99132948 | E48: =E44/E46 -> 0.89548694 | F48: =F44/F46 -> 0.81149425 | G48: =G44/G46 -> 1.0480349 | H48: =AVERAGE(C48:G48) -> 0.95605924 | I48: 0.95605924 | J48: 0.95605924 | K48: 0.95605924 | L48: 0.95605924
B49: Deferred tax | C49: =C45/C46 -> -0.033950617 | D49: =D45/D46 -> 0.0086705202 | E49: =E45/E46 -> 0.10451306 | F49: =F45/F46 -> 0.18850575 | G49: =G45/G46 -> -0.048034934 | H49: =AVERAGE(C49:G49) -> 0.043940756 | I49: 0.043940756 | J49: 0.043940756 | K49: 0.043940756 | L49: 0.043940756
B50: Total Tax | C50: =SUM(C48:C49) -> 1 | D50: =SUM(D48:D49) -> 1 | E50: =SUM(E48:E49) -> 1 | F50: =SUM(F48:F49) -> 1 | G50: =SUM(G48:G49) -> 1 | H50: =SUM(H48:H49) -> 1 | I50: 1 | J50: 1 | K50: 1 | L50: 1

Sheet Asset Schedule
E2: ARICO LTD
B10: PARTICULARS | C10: 2021 A | D10: 2022 A | E10: 2023A | F10: 2024A | G10: 2025A | H10: 2026 E | I10: 2027 E | J10: 2028 E | K10: 2029 E | L10: 2030 E
B14: Opening balance | D14: =C19 -> 1023 | E14: =D19 -> 1145 | F14: =E19 -> 1451 | G14: =F19 -> 1905 | H14: =G19 -> 1941 | I14: =H19 -> 1891.2744 | J14: =I19 -> 1892.3539 | K14: =J19 -> 1972.8711 | L14: =K19 -> 2139.806
B15: Addition | C15: =-('Cashflow statement'!C40) -> 142 | D15: =-('Cashflow statement'!D40) -> 132 | E15: =-('Cashflow statement'!E40) -> 182 | F15: =-('Cashflow statement'!F40) -> 153 | G15: =-('Cashflow statement'!G40) -> 161 | H15: =H23 -> 204.49503 | I15: =I23 -> 260.69334 | J15: =J23 -> 347.23557 | K15: =K23 -> 456.84558 | L15: =L23 -> 580.41876
